<?xml version="1.0" encoding="utf-8"?>
<robot name="open_critter">
  <link name="base_link">
    <visual>
      <origin rpy="0 0 3.14" xyz="0.0 0.0 0.04"/>
      <geometry>
        <mesh filename="package://open_critter/meshes/collada/body.dae"/>
      </geometry>
    </visual>
    <collision>
      <origin rpy="0 0 3.14" xyz="0.0 0.0 0.04"/>
      <geometry>
        <mesh filename="package://open_critter/meshes/collada/body.dae"/>
      </geometry>
    </collision>
    <inertial>
      <origin rpy="0 0 0" xyz="0 0 0"/>
      <geometry>
        <box size="0.1 0.05 0.03"/>
      </geometry>
      <mass value="0.2"/>
      <inertia ixx="5.66666666667e-05" ixy="0" ixz="0" iyy="0.000181666666667" iyz="0" izz="0.000181666666667"/>
    </inertial>
  </link>
  <joint name="front_left_base" type="fixed">
    <parent link="base_link"/>
    <child link="front_left_coxa_servo"/>
    <origin rpy="0 0 3.14159265359" xyz="0.03 0.035 0.0225"/>
  </joint>
  <link name="front_left_coxa_servo">
    <visual>
      <origin rpy="0 0 0" xyz="0 0 0"/>
      <geometry>
        <mesh filename="package://open_critter/meshes/collada/servo.dae"/>
      </geometry>
    </visual>
    <!-- <collision>
      <origin rpy="0 0 0" xyz="0 0 0"/>
      <geometry>
        <mesh filename="package://open_critter/meshes/collada/servo.dae"/>
      </geometry>
    </collision> -->
    <inertial>
      <origin rpy="0 0 0" xyz="0 0 0"/>
      <geometry>
        <box size="0.02 0.01 0.03"/>
      </geometry>
      <mass value="0.009"/>
      <inertia ixx="7.5e-07" ixy="0" ixz="0" iyy="9.75e-07" iyz="0" izz="9.75e-07"/>
    </inertial>
  </link>
  <joint name="front_left_coxa_joint" type="revolute">
    <parent link="front_left_coxa_servo"/>
    <child link="front_left_coxa_link"/>
    <origin rpy="0 0 -0.785398163397" xyz="-0.005 0 -0.002"/>
    <limit effort="10" lower="-1.0" upper="1.0" velocity="4.0"/>
    <axis xyz="0 0 1"/>
  </joint>
  <transmission name="front_left_coxa_transmission">
    <type>transmission_interface/SimpleTransmission</type>
    <joint name="front_left_coxa_joint">
      <hardwareInterface>hardware_interface/PositionJointInterface</hardwareInterface>
    </joint>
    <actuator name="front_left_coxa_actuator">
      <hardwareInterface>hardware_interface/PositionJointInterface</hardwareInterface>
      <mechanicalReduction>1.0</mechanicalReduction>
      <motorTorqueConstant>10</motorTorqueConstant>
    </actuator>
  </transmission>
  <link name="front_left_coxa_link">
    <visual>
      <origin rpy="0 0 0" xyz="0.002 -0.016 0"/>
      <geometry>
        <mesh filename="package://open_critter/meshes/collada/coxa_front.dae"/>
      </geometry>
    </visual>
    <collision>
      <origin rpy="0 0 0" xyz="0.002 -0.016 0"/>
      <geometry>
        <mesh filename="package://open_critter/meshes/collada/coxa_front.dae"/>
      </geometry>
    </collision>
    <inertial>
      <origin rpy="0 0 0" xyz="0 0 0"/>
      <geometry>
        <box size="0.04 0.01 0.03"/>
      </geometry>
      <mass value="0.001"/>
      <inertia ixx="8.33333333333e-08" ixy="0" ixz="0" iyy="2.08333333333e-07" iyz="0" izz="2.08333333333e-07"/>
    </inertial>
  </link>
  <gazebo reference="front_left_coxa_link">
    <gravity>true</gravity>
    <selfCollide>true</selfCollide>
  </gazebo>
  <joint name="front_left_femur_servo_to_coxa_joint" type="fixed">
    <parent link="front_left_coxa_link"/>
    <child link="front_left_femur_servo"/>
    <origin rpy="0 0 0" xyz="-0.005 -0.0275 0"/>
  </joint>
  <link name="front_left_femur_servo">
    <visual>
      <origin rpy="0 1.57079632679 3.14159265359" xyz="0 0 0"/>
      <geometry>
        <mesh filename="package://open_critter/meshes/collada/servo.dae"/>
      </geometry>
    </visual>
    <!-- <collision>
      <origin rpy="0 ${pi/2} ${nyaw}" xyz="0 0 0"/>
      <geometry>
        <mesh filename="package://open_critter/meshes/collada/servo.dae"/>
      </geometry>
    </collision> -->
    <inertial>
      <origin rpy="0 1.57079632679 3.14159265359" xyz="0 0 0"/>
      <geometry>
        <box size="0.02 0.01 0.03"/>
      </geometry>
      <mass value="0.009"/>
      <inertia ixx="7.5e-07" ixy="0" ixz="0" iyy="9.75e-07" iyz="0" izz="9.75e-07"/>
    </inertial>
  </link>
  <joint name="front_left_femur_joint" type="revolute">
    <parent link="front_left_femur_servo"/>
    <child link="front_left_femur_link"/>
    <origin rpy="-0.392699081699 0 0" xyz="0 0 0.005"/>
    <limit effort="10" lower="-1.0" upper="1.0" velocity="4.0"/>
    <axis xyz="-1.0 0 0"/>
  </joint>
  <transmission name="front_left_femur_transmission">
    <type>transmission_interface/SimpleTransmission</type>
    <joint name="front_left_femur_joint">
      <hardwareInterface>hardware_interface/PositionJointInterface</hardwareInterface>
    </joint>
    <actuator name="front_left_femur_actuator">
      <hardwareInterface>hardware_interface/PositionJointInterface</hardwareInterface>
      <mechanicalReduction>1.0</mechanicalReduction>
      <motorTorqueConstant>10</motorTorqueConstant>
    </actuator>
  </transmission>
  <link name="front_left_femur_link">
    <visual>
      <origin rpy="0 3.14159265359 0" xyz="0.0025 -0.0275 0"/>
      <geometry>
        <mesh filename="package://open_critter/meshes/collada/femur.dae"/>
      </geometry>
    </visual>
    <collision>
      <origin rpy="0 3.14159265359 0" xyz="0.0025 -0.0275 0"/>
      <geometry>
        <mesh filename="package://open_critter/meshes/collada/femur.dae"/>
      </geometry>
    </collision>
    <inertial>
      <origin rpy="0 0 0" xyz="0 0 0"/>
      <geometry>
        <box size="0.05 0.01 0.03"/>
      </geometry>
      <mass value="0.002"/>
      <inertia ixx="1.66666666667e-07" ixy="0" ixz="0" iyy="5.66666666667e-07" iyz="0" izz="5.66666666667e-07"/>
    </inertial>
  </link>
  <gazebo reference="front_left_femur_link">
    <gravity>true</gravity>
    <selfCollide>true</selfCollide>
  </gazebo>
  <joint name="front_left_tibia_joint" type="revolute">
    <parent link="front_left_femur_link"/>
    <child link="front_left_tibia_servo"/>
    <origin rpy="-0.392699081699 0 0" xyz="0 -0.055 0"/>
    <limit effort="10" lower="-1.0" upper="1.0" velocity="4.0"/>
    <axis xyz="1.0 0 0"/>
    <dynamics friction="0.7"/>
  </joint>
  <transmission name="front_left_tibia_transmission">
    <type>transmission_interface/SimpleTransmission</type>
    <joint name="front_left_tibia_joint">
      <hardwareInterface>hardware_interface/PositionJointInterface</hardwareInterface>
    </joint>
    <actuator name="front_left_tibia_actuator">
      <hardwareInterface>hardware_interface/PositionJointInterface</hardwareInterface>
      <mechanicalReduction>1.0</mechanicalReduction>
      <motorTorqueConstant>10</motorTorqueConstant>
    </actuator>
  </transmission>
  <link name="front_left_tibia_servo">
    <visual>
      <origin rpy="0 1.57079632679 3.14159265359" xyz="0.0 0 -0.005"/>
      <geometry>
        <mesh filename="package://open_critter/meshes/collada/servo.dae"/>
      </geometry>
    </visual>
    <!-- <collision>
      <origin rpy="0 ${pi/2} ${nyaw}" xyz="${side*servo_x} 0 -0.005"/>
      <geometry>
        <mesh filename="package://open_critter/meshes/collada/servo.dae"/>
      </geometry>
    </collision> -->
    <inertial>
      <origin rpy="0 1.57079632679 3.14159265359" xyz="0.0 0 -0.005"/>
      <geometry>
        <box size="0.02 0.01 0.03"/>
      </geometry>
      <mass value="0.009"/>
      <inertia ixx="7.5e-07" ixy="0" ixz="0" iyy="9.75e-07" iyz="0" izz="9.75e-07"/>
    </inertial>
  </link>
  <joint name="front_left_tibia_servo_to_femur_joint" type="fixed">
    <parent link="front_left_tibia_servo"/>
    <child link="front_left_tibia_link"/>
    <origin rpy="0 0 0" xyz="0 0 0"/>
  </joint>
  <link name="front_left_tibia_link">
    <visual>
      <origin rpy="0 0 3.14159265359" xyz="0.0075 0 -0.03"/>
      <geometry>
        <mesh filename="package://open_critter/meshes/collada/tibia_rear.dae"/>
      </geometry>
    </visual>
    <collision>
      <origin rpy="0 0 3.14159265359" xyz="0.0075 0 -0.03"/>
      <geometry>
        <mesh filename="package://open_critter/meshes/collada/tibia_rear.dae"/>
      </geometry>
    </collision>
    <inertial>
      <origin rpy="0 0 0" xyz="0 0 0"/>
      <geometry>
        <box size="0.1 0.005 0.005"/>
      </geometry>
      <mass value="0.001"/>
      <inertia ixx="4.16666666667e-09" ixy="0" ixz="0" iyy="8.35416666667e-07" iyz="0" izz="8.35416666667e-07"/>
    </inertial>
  </link>
  <gazebo reference="front_left_tibia_link">
    <mu1 value="5.0"/>
    <mu2 value="0.5"/>
    <kp value="10000000.0"/>
    <kd value="1.0"/>
    <fdir1 value="1 0 0"/>
    <turnGravityOff>false</turnGravityOff>
    <selfCollide>true</selfCollide>
  </gazebo>
  <joint name="front_left_tibia_paw_joint" type="fixed">
    <parent link="front_left_tibia_link"/>
    <child link="front_left_paw_link"/>
    <origin rpy="0 0 0" xyz="0.0015 0 -0.08"/>
  </joint>
  <link name="front_left_paw_link">
    <visual>
      <origin rpy="0 0 0" xyz="0 0 0"/>
      <geometry>
        <sphere radius="0.005"/>
      </geometry>
    </visual>
    <collision>
      <origin rpy="0 0 0" xyz="0 0 0"/>
      <geometry>
        <sphere radius="0.005"/>
      </geometry>
    </collision>
    <inertial>
      <origin rpy="0 0 0" xyz="0 0 0"/>
      <geometry>
        <sphere radius="0.005"/>
      </geometry>
      <mass value="0.001"/>
      <inertia ixx="1e-08" ixy="0" ixz="0" iyy="1e-08" iyz="0" izz="1e-08"/>
    </inertial>
  </link>
  <gazebo reference="front_left_paw_link">
    <gravity>true</gravity>
    <selfCollide>true</selfCollide>
    <mu1>0.1</mu1>
    <mu2>0.1</mu2>
    <kp>1000000.0</kp>
    <kd>1.0</kd>
    <fdir1>0 1 0</fdir1>
    <maxContacts>1</maxContacts>
    <minDepth>0.0001</minDepth>
    <collision name="front_left__paw_link_collision">
      <geometry>
        <sphere>
          <radius>0.005</radius>
        </sphere>
      </geometry>
      <surface>
        <friction>
          <torsional>
            <coefficient>10</coefficient>
            <use_patch_radius>false</use_patch_radius>
            <surface_radius>0.01</surface_radius>
            <patch_radius>0.01</patch_radius>
          </torsional>
        </friction>
        <contact>
          <poissons_ratio>0.01</poissons_ratio>
          <elastic_modulus>1e8</elastic_modulus>
        </contact>
      </surface>
    </collision>
    <material>Gazebo/Red</material>
  </gazebo>
  <joint name="rear_left_base" type="fixed">
    <parent link="base_link"/>
    <child link="rear_left_coxa_servo"/>
    <origin rpy="0 0 0" xyz="-0.03 0.035 0.0225"/>
  </joint>
  <link name="rear_left_coxa_servo">
    <visual>
      <origin rpy="0 0 0" xyz="0 0 0"/>
      <geometry>
        <mesh filename="package://open_critter/meshes/collada/servo.dae"/>
      </geometry>
    </visual>
    <!-- <collision>
      <origin rpy="0 0 0" xyz="0 0 0"/>
      <geometry>
        <mesh filename="package://open_critter/meshes/collada/servo.dae"/>
      </geometry>
    </collision> -->
    <inertial>
      <origin rpy="0 0 0" xyz="0 0 0"/>
      <geometry>
        <box size="0.02 0.01 0.03"/>
      </geometry>
      <mass value="0.009"/>
      <inertia ixx="7.5e-07" ixy="0" ixz="0" iyy="9.75e-07" iyz="0" izz="9.75e-07"/>
    </inertial>
  </link>
  <joint name="rear_left_coxa_joint" type="revolute">
    <parent link="rear_left_coxa_servo"/>
    <child link="rear_left_coxa_link"/>
    <origin rpy="0 0 3.92699081699" xyz="-0.005 0 -0.002"/>
    <limit effort="10" lower="-1.0" upper="1.0" velocity="4.0"/>
    <axis xyz="0 0 1"/>
  </joint>
  <transmission name="rear_left_coxa_transmission">
    <type>transmission_interface/SimpleTransmission</type>
    <joint name="rear_left_coxa_joint">
      <hardwareInterface>hardware_interface/PositionJointInterface</hardwareInterface>
    </joint>
    <actuator name="rear_left_coxa_actuator">
      <hardwareInterface>hardware_interface/PositionJointInterface</hardwareInterface>
      <mechanicalReduction>1.0</mechanicalReduction>
      <motorTorqueConstant>10</motorTorqueConstant>
    </actuator>
  </transmission>
  <link name="rear_left_coxa_link">
    <visual>
      <origin rpy="0 0 3.14159265359" xyz="-0.002 -0.016 0"/>
      <geometry>
        <mesh filename="package://open_critter/meshes/collada/coxa_rear.dae"/>
      </geometry>
    </visual>
    <collision>
      <origin rpy="0 0 3.14159265359" xyz="-0.002 -0.016 0"/>
      <geometry>
        <mesh filename="package://open_critter/meshes/collada/coxa_rear.dae"/>
      </geometry>
    </collision>
    <inertial>
      <origin rpy="0 0 0" xyz="0 0 0"/>
      <geometry>
        <box size="0.04 0.01 0.03"/>
      </geometry>
      <mass value="0.001"/>
      <inertia ixx="8.33333333333e-08" ixy="0" ixz="0" iyy="2.08333333333e-07" iyz="0" izz="2.08333333333e-07"/>
    </inertial>
  </link>
  <gazebo reference="rear_left_coxa_link">
    <gravity>true</gravity>
    <selfCollide>true</selfCollide>
  </gazebo>
  <joint name="rear_left_femur_servo_to_coxa_joint" type="fixed">
    <parent link="rear_left_coxa_link"/>
    <child link="rear_left_femur_servo"/>
    <origin rpy="0 0 0" xyz="0.005 -0.0275 0"/>
  </joint>
  <link name="rear_left_femur_servo">
    <visual>
      <origin rpy="0 1.57079632679 0" xyz="0 0 0"/>
      <geometry>
        <mesh filename="package://open_critter/meshes/collada/servo.dae"/>
      </geometry>
    </visual>
    <!-- <collision>
      <origin rpy="0 ${pi/2} ${nyaw}" xyz="0 0 0"/>
      <geometry>
        <mesh filename="package://open_critter/meshes/collada/servo.dae"/>
      </geometry>
    </collision> -->
    <inertial>
      <origin rpy="0 1.57079632679 0" xyz="0 0 0"/>
      <geometry>
        <box size="0.02 0.01 0.03"/>
      </geometry>
      <mass value="0.009"/>
      <inertia ixx="7.5e-07" ixy="0" ixz="0" iyy="9.75e-07" iyz="0" izz="9.75e-07"/>
    </inertial>
  </link>
  <joint name="rear_left_femur_joint" type="revolute">
    <parent link="rear_left_femur_servo"/>
    <child link="rear_left_femur_link"/>
    <origin rpy="-0.392699081699 0 0" xyz="-0.005 0 0.005"/>
    <limit effort="10" lower="-1.0" upper="1.0" velocity="4.0"/>
    <axis xyz="1.0 0 0"/>
  </joint>
  <transmission name="rear_left_femur_transmission">
    <type>transmission_interface/SimpleTransmission</type>
    <joint name="rear_left_femur_joint">
      <hardwareInterface>hardware_interface/PositionJointInterface</hardwareInterface>
    </joint>
    <actuator name="rear_left_femur_actuator">
      <hardwareInterface>hardware_interface/PositionJointInterface</hardwareInterface>
      <mechanicalReduction>1.0</mechanicalReduction>
      <motorTorqueConstant>10</motorTorqueConstant>
    </actuator>
  </transmission>
  <link name="rear_left_femur_link">
    <visual>
      <origin rpy="0 0 0" xyz="0.0025 -0.0275 0"/>
      <geometry>
        <mesh filename="package://open_critter/meshes/collada/femur.dae"/>
      </geometry>
    </visual>
    <collision>
      <origin rpy="0 0 0" xyz="0.0025 -0.0275 0"/>
      <geometry>
        <mesh filename="package://open_critter/meshes/collada/femur.dae"/>
      </geometry>
    </collision>
    <inertial>
      <origin rpy="0 0 0" xyz="0 0 0"/>
      <geometry>
        <box size="0.05 0.01 0.03"/>
      </geometry>
      <mass value="0.002"/>
      <inertia ixx="1.66666666667e-07" ixy="0" ixz="0" iyy="5.66666666667e-07" iyz="0" izz="5.66666666667e-07"/>
    </inertial>
  </link>
  <gazebo reference="rear_left_femur_link">
    <gravity>true</gravity>
    <selfCollide>true</selfCollide>
  </gazebo>
  <joint name="rear_left_tibia_joint" type="revolute">
    <parent link="rear_left_femur_link"/>
    <child link="rear_left_tibia_servo"/>
    <origin rpy="-0.392699081699 0 0" xyz="0 -0.055 0"/>
    <limit effort="10" lower="-1.0" upper="1.0" velocity="4.0"/>
    <axis xyz="-1.0 0 0"/>
    <dynamics friction="0.7"/>
  </joint>
  <transmission name="rear_left_tibia_transmission">
    <type>transmission_interface/SimpleTransmission</type>
    <joint name="rear_left_tibia_joint">
      <hardwareInterface>hardware_interface/PositionJointInterface</hardwareInterface>
    </joint>
    <actuator name="rear_left_tibia_actuator">
      <hardwareInterface>hardware_interface/PositionJointInterface</hardwareInterface>
      <mechanicalReduction>1.0</mechanicalReduction>
      <motorTorqueConstant>10</motorTorqueConstant>
    </actuator>
  </transmission>
  <link name="rear_left_tibia_servo">
    <visual>
      <origin rpy="0 1.57079632679 0" xyz="0.005 0 -0.005"/>
      <geometry>
        <mesh filename="package://open_critter/meshes/collada/servo.dae"/>
      </geometry>
    </visual>
    <!-- <collision>
      <origin rpy="0 ${pi/2} ${nyaw}" xyz="${side*servo_x} 0 -0.005"/>
      <geometry>
        <mesh filename="package://open_critter/meshes/collada/servo.dae"/>
      </geometry>
    </collision> -->
    <inertial>
      <origin rpy="0 1.57079632679 0" xyz="0.005 0 -0.005"/>
      <geometry>
        <box size="0.02 0.01 0.03"/>
      </geometry>
      <mass value="0.009"/>
      <inertia ixx="7.5e-07" ixy="0" ixz="0" iyy="9.75e-07" iyz="0" izz="9.75e-07"/>
    </inertial>
  </link>
  <joint name="rear_left_tibia_servo_to_femur_joint" type="fixed">
    <parent link="rear_left_tibia_servo"/>
    <child link="rear_left_tibia_link"/>
    <origin rpy="0 0 0" xyz="0 0 0"/>
  </joint>
  <link name="rear_left_tibia_link">
    <visual>
      <origin rpy="0 0 0" xyz="-0.0025 0 -0.03"/>
      <geometry>
        <mesh filename="package://open_critter/meshes/collada/tibia_front.dae"/>
      </geometry>
    </visual>
    <collision>
      <origin rpy="0 0 0" xyz="-0.0025 0 -0.03"/>
      <geometry>
        <mesh filename="package://open_critter/meshes/collada/tibia_front.dae"/>
      </geometry>
    </collision>
    <inertial>
      <origin rpy="0 0 0" xyz="0 0 0"/>
      <geometry>
        <box size="0.1 0.005 0.005"/>
      </geometry>
      <mass value="0.001"/>
      <inertia ixx="4.16666666667e-09" ixy="0" ixz="0" iyy="8.35416666667e-07" iyz="0" izz="8.35416666667e-07"/>
    </inertial>
  </link>
  <gazebo reference="rear_left_tibia_link">
    <mu1 value="5.0"/>
    <mu2 value="0.5"/>
    <kp value="10000000.0"/>
    <kd value="1.0"/>
    <fdir1 value="1 0 0"/>
    <turnGravityOff>false</turnGravityOff>
    <selfCollide>true</selfCollide>
  </gazebo>
  <joint name="rear_left_tibia_paw_joint" type="fixed">
    <parent link="rear_left_tibia_link"/>
    <child link="rear_left_paw_link"/>
    <origin rpy="0 0 0" xyz="0.0035 0 -0.08"/>
  </joint>
  <link name="rear_left_paw_link">
    <visual>
      <origin rpy="0 0 0" xyz="0 0 0"/>
      <geometry>
        <sphere radius="0.005"/>
      </geometry>
    </visual>
    <collision>
      <origin rpy="0 0 0" xyz="0 0 0"/>
      <geometry>
        <sphere radius="0.005"/>
      </geometry>
    </collision>
    <inertial>
      <origin rpy="0 0 0" xyz="0 0 0"/>
      <geometry>
        <sphere radius="0.005"/>
      </geometry>
      <mass value="0.001"/>
      <inertia ixx="1e-08" ixy="0" ixz="0" iyy="1e-08" iyz="0" izz="1e-08"/>
    </inertial>
  </link>
  <gazebo reference="rear_left_paw_link">
    <gravity>true</gravity>
    <selfCollide>true</selfCollide>
    <mu1>0.1</mu1>
    <mu2>0.1</mu2>
    <kp>1000000.0</kp>
    <kd>1.0</kd>
    <fdir1>0 1 0</fdir1>
    <maxContacts>1</maxContacts>
    <minDepth>0.0001</minDepth>
    <collision name="rear_left__paw_link_collision">
      <geometry>
        <sphere>
          <radius>0.005</radius>
        </sphere>
      </geometry>
      <surface>
        <friction>
          <torsional>
            <coefficient>10</coefficient>
            <use_patch_radius>false</use_patch_radius>
            <surface_radius>0.01</surface_radius>
            <patch_radius>0.01</patch_radius>
          </torsional>
        </friction>
        <contact>
          <poissons_ratio>0.01</poissons_ratio>
          <elastic_modulus>1e8</elastic_modulus>
        </contact>
      </surface>
    </collision>
    <material>Gazebo/Red</material>
  </gazebo>
  <joint name="rear_right_base" type="fixed">
    <parent link="base_link"/>
    <child link="rear_right_coxa_servo"/>
    <origin rpy="0 0 0" xyz="-0.03 -0.035 0.0225"/>
  </joint>
  <link name="rear_right_coxa_servo">
    <visual>
      <origin rpy="0 0 0" xyz="0 0 0"/>
      <geometry>
        <mesh filename="package://open_critter/meshes/collada/servo.dae"/>
      </geometry>
    </visual>
    <!-- <collision>
      <origin rpy="0 0 0" xyz="0 0 0"/>
      <geometry>
        <mesh filename="package://open_critter/meshes/collada/servo.dae"/>
      </geometry>
    </collision> -->
    <inertial>
      <origin rpy="0 0 0" xyz="0 0 0"/>
      <geometry>
        <box size="0.02 0.01 0.03"/>
      </geometry>
      <mass value="0.009"/>
      <inertia ixx="7.5e-07" ixy="0" ixz="0" iyy="9.75e-07" iyz="0" izz="9.75e-07"/>
    </inertial>
  </link>
  <joint name="rear_right_coxa_joint" type="revolute">
    <parent link="rear_right_coxa_servo"/>
    <child link="rear_right_coxa_link"/>
    <origin rpy="0 0 -0.785398163397" xyz="-0.005 0 -0.002"/>
    <limit effort="10" lower="-1.0" upper="1.0" velocity="4.0"/>
    <axis xyz="0 0 1"/>
  </joint>
  <transmission name="rear_right_coxa_transmission">
    <type>transmission_interface/SimpleTransmission</type>
    <joint name="rear_right_coxa_joint">
      <hardwareInterface>hardware_interface/PositionJointInterface</hardwareInterface>
    </joint>
    <actuator name="rear_right_coxa_actuator">
      <hardwareInterface>hardware_interface/PositionJointInterface</hardwareInterface>
      <mechanicalReduction>1.0</mechanicalReduction>
      <motorTorqueConstant>10</motorTorqueConstant>
    </actuator>
  </transmission>
  <link name="rear_right_coxa_link">
    <visual>
      <origin rpy="0 0 0" xyz="0.002 -0.016 0"/>
      <geometry>
        <mesh filename="package://open_critter/meshes/collada/coxa_front.dae"/>
      </geometry>
    </visual>
    <collision>
      <origin rpy="0 0 0" xyz="0.002 -0.016 0"/>
      <geometry>
        <mesh filename="package://open_critter/meshes/collada/coxa_front.dae"/>
      </geometry>
    </collision>
    <inertial>
      <origin rpy="0 0 0" xyz="0 0 0"/>
      <geometry>
        <box size="0.04 0.01 0.03"/>
      </geometry>
      <mass value="0.001"/>
      <inertia ixx="8.33333333333e-08" ixy="0" ixz="0" iyy="2.08333333333e-07" iyz="0" izz="2.08333333333e-07"/>
    </inertial>
  </link>
  <gazebo reference="rear_right_coxa_link">
    <gravity>true</gravity>
    <selfCollide>true</selfCollide>
  </gazebo>
  <joint name="rear_right_femur_servo_to_coxa_joint" type="fixed">
    <parent link="rear_right_coxa_link"/>
    <child link="rear_right_femur_servo"/>
    <origin rpy="0 0 0" xyz="-0.005 -0.0275 0"/>
  </joint>
  <link name="rear_right_femur_servo">
    <visual>
      <origin rpy="0 1.57079632679 3.14159265359" xyz="0 0 0"/>
      <geometry>
        <mesh filename="package://open_critter/meshes/collada/servo.dae"/>
      </geometry>
    </visual>
    <!-- <collision>
      <origin rpy="0 ${pi/2} ${nyaw}" xyz="0 0 0"/>
      <geometry>
        <mesh filename="package://open_critter/meshes/collada/servo.dae"/>
      </geometry>
    </collision> -->
    <inertial>
      <origin rpy="0 1.57079632679 3.14159265359" xyz="0 0 0"/>
      <geometry>
        <box size="0.02 0.01 0.03"/>
      </geometry>
      <mass value="0.009"/>
      <inertia ixx="7.5e-07" ixy="0" ixz="0" iyy="9.75e-07" iyz="0" izz="9.75e-07"/>
    </inertial>
  </link>
  <joint name="rear_right_femur_joint" type="revolute">
    <parent link="rear_right_femur_servo"/>
    <child link="rear_right_femur_link"/>
    <origin rpy="-0.392699081699 0 0" xyz="0 0 0.005"/>
    <limit effort="10" lower="-1.0" upper="1.0" velocity="4.0"/>
    <axis xyz="-1.0 0 0"/>
  </joint>
  <transmission name="rear_right_femur_transmission">
    <type>transmission_interface/SimpleTransmission</type>
    <joint name="rear_right_femur_joint">
      <hardwareInterface>hardware_interface/PositionJointInterface</hardwareInterface>
    </joint>
    <actuator name="rear_right_femur_actuator">
      <hardwareInterface>hardware_interface/PositionJointInterface</hardwareInterface>
      <mechanicalReduction>1.0</mechanicalReduction>
      <motorTorqueConstant>10</motorTorqueConstant>
    </actuator>
  </transmission>
  <link name="rear_right_femur_link">
    <visual>
      <origin rpy="0 3.14159265359 0" xyz="0.0025 -0.0275 0"/>
      <geometry>
        <mesh filename="package://open_critter/meshes/collada/femur.dae"/>
      </geometry>
    </visual>
    <collision>
      <origin rpy="0 3.14159265359 0" xyz="0.0025 -0.0275 0"/>
      <geometry>
        <mesh filename="package://open_critter/meshes/collada/femur.dae"/>
      </geometry>
    </collision>
    <inertial>
      <origin rpy="0 0 0" xyz="0 0 0"/>
      <geometry>
        <box size="0.05 0.01 0.03"/>
      </geometry>
      <mass value="0.002"/>
      <inertia ixx="1.66666666667e-07" ixy="0" ixz="0" iyy="5.66666666667e-07" iyz="0" izz="5.66666666667e-07"/>
    </inertial>
  </link>
  <gazebo reference="rear_right_femur_link">
    <gravity>true</gravity>
    <selfCollide>true</selfCollide>
  </gazebo>
  <joint name="rear_right_tibia_joint" type="revolute">
    <parent link="rear_right_femur_link"/>
    <child link="rear_right_tibia_servo"/>
    <origin rpy="-0.392699081699 0 0" xyz="0 -0.055 0"/>
    <limit effort="10" lower="-1.0" upper="1.0" velocity="4.0"/>
    <axis xyz="1.0 0 0"/>
    <dynamics friction="0.7"/>
  </joint>
  <transmission name="rear_right_tibia_transmission">
    <type>transmission_interface/SimpleTransmission</type>
    <joint name="rear_right_tibia_joint">
      <hardwareInterface>hardware_interface/PositionJointInterface</hardwareInterface>
    </joint>
    <actuator name="rear_right_tibia_actuator">
      <hardwareInterface>hardware_interface/PositionJointInterface</hardwareInterface>
      <mechanicalReduction>1.0</mechanicalReduction>
      <motorTorqueConstant>10</motorTorqueConstant>
    </actuator>
  </transmission>
  <link name="rear_right_tibia_servo">
    <visual>
      <origin rpy="0 1.57079632679 3.14159265359" xyz="0.0 0 -0.005"/>
      <geometry>
        <mesh filename="package://open_critter/meshes/collada/servo.dae"/>
      </geometry>
    </visual>
    <!-- <collision>
      <origin rpy="0 ${pi/2} ${nyaw}" xyz="${side*servo_x} 0 -0.005"/>
      <geometry>
        <mesh filename="package://open_critter/meshes/collada/servo.dae"/>
      </geometry>
    </collision> -->
    <inertial>
      <origin rpy="0 1.57079632679 3.14159265359" xyz="0.0 0 -0.005"/>
      <geometry>
        <box size="0.02 0.01 0.03"/>
      </geometry>
      <mass value="0.009"/>
      <inertia ixx="7.5e-07" ixy="0" ixz="0" iyy="9.75e-07" iyz="0" izz="9.75e-07"/>
    </inertial>
  </link>
  <joint name="rear_right_tibia_servo_to_femur_joint" type="fixed">
    <parent link="rear_right_tibia_servo"/>
    <child link="rear_right_tibia_link"/>
    <origin rpy="0 0 0" xyz="0 0 0"/>
  </joint>
  <link name="rear_right_tibia_link">
    <visual>
      <origin rpy="0 0 3.14159265359" xyz="0.0075 0 -0.03"/>
      <geometry>
        <mesh filename="package://open_critter/meshes/collada/tibia_rear.dae"/>
      </geometry>
    </visual>
    <collision>
      <origin rpy="0 0 3.14159265359" xyz="0.0075 0 -0.03"/>
      <geometry>
        <mesh filename="package://open_critter/meshes/collada/tibia_rear.dae"/>
      </geometry>
    </collision>
    <inertial>
      <origin rpy="0 0 0" xyz="0 0 0"/>
      <geometry>
        <box size="0.1 0.005 0.005"/>
      </geometry>
      <mass value="0.001"/>
      <inertia ixx="4.16666666667e-09" ixy="0" ixz="0" iyy="8.35416666667e-07" iyz="0" izz="8.35416666667e-07"/>
    </inertial>
  </link>
  <gazebo reference="rear_right_tibia_link">
    <mu1 value="5.0"/>
    <mu2 value="0.5"/>
    <kp value="10000000.0"/>
    <kd value="1.0"/>
    <fdir1 value="1 0 0"/>
    <turnGravityOff>false</turnGravityOff>
    <selfCollide>true</selfCollide>
  </gazebo>
  <joint name="rear_right_tibia_paw_joint" type="fixed">
    <parent link="rear_right_tibia_link"/>
    <child link="rear_right_paw_link"/>
    <origin rpy="0 0 0" xyz="0.0015 0 -0.08"/>
  </joint>
  <link name="rear_right_paw_link">
    <visual>
      <origin rpy="0 0 0" xyz="0 0 0"/>
      <geometry>
        <sphere radius="0.005"/>
      </geometry>
    </visual>
    <collision>
      <origin rpy="0 0 0" xyz="0 0 0"/>
      <geometry>
        <sphere radius="0.005"/>
      </geometry>
    </collision>
    <inertial>
      <origin rpy="0 0 0" xyz="0 0 0"/>
      <geometry>
        <sphere radius="0.005"/>
      </geometry>
      <mass value="0.001"/>
      <inertia ixx="1e-08" ixy="0" ixz="0" iyy="1e-08" iyz="0" izz="1e-08"/>
    </inertial>
  </link>
  <gazebo reference="rear_right_paw_link">
    <gravity>true</gravity>
    <selfCollide>true</selfCollide>
    <mu1>0.1</mu1>
    <mu2>0.1</mu2>
    <kp>1000000.0</kp>
    <kd>1.0</kd>
    <fdir1>0 1 0</fdir1>
    <maxContacts>1</maxContacts>
    <minDepth>0.0001</minDepth>
    <collision name="rear_right__paw_link_collision">
      <geometry>
        <sphere>
          <radius>0.005</radius>
        </sphere>
      </geometry>
      <surface>
        <friction>
          <torsional>
            <coefficient>10</coefficient>
            <use_patch_radius>false</use_patch_radius>
            <surface_radius>0.01</surface_radius>
            <patch_radius>0.01</patch_radius>
          </torsional>
        </friction>
        <contact>
          <poissons_ratio>0.01</poissons_ratio>
          <elastic_modulus>1e8</elastic_modulus>
        </contact>
      </surface>
    </collision>
    <material>Gazebo/Red</material>
  </gazebo>
  <joint name="front_right_base" type="fixed">
    <parent link="base_link"/>
    <child link="front_right_coxa_servo"/>
    <origin rpy="0 0 3.14159265359" xyz="0.03 -0.035 0.0225"/>
  </joint>
  <link name="front_right_coxa_servo">
    <visual>
      <origin rpy="0 0 0" xyz="0 0 0"/>
      <geometry>
        <mesh filename="package://open_critter/meshes/collada/servo.dae"/>
      </geometry>
    </visual>
    <!-- <collision>
      <origin rpy="0 0 0" xyz="0 0 0"/>
      <geometry>
        <mesh filename="package://open_critter/meshes/collada/servo.dae"/>
      </geometry>
    </collision> -->
    <inertial>
      <origin rpy="0 0 0" xyz="0 0 0"/>
      <geometry>
        <box size="0.02 0.01 0.03"/>
      </geometry>
      <mass value="0.009"/>
      <inertia ixx="7.5e-07" ixy="0" ixz="0" iyy="9.75e-07" iyz="0" izz="9.75e-07"/>
    </inertial>
  </link>
  <joint name="front_right_coxa_joint" type="revolute">
    <parent link="front_right_coxa_servo"/>
    <child link="front_right_coxa_link"/>
    <origin rpy="0 0 3.92699081699" xyz="-0.005 0 -0.002"/>
    <limit effort="10" lower="-1.0" upper="1.0" velocity="4.0"/>
    <axis xyz="0 0 1"/>
  </joint>
  <transmission name="front_right_coxa_transmission">
    <type>transmission_interface/SimpleTransmission</type>
    <joint name="front_right_coxa_joint">
      <hardwareInterface>hardware_interface/PositionJointInterface</hardwareInterface>
    </joint>
    <actuator name="front_right_coxa_actuator">
      <hardwareInterface>hardware_interface/PositionJointInterface</hardwareInterface>
      <mechanicalReduction>1.0</mechanicalReduction>
      <motorTorqueConstant>10</motorTorqueConstant>
    </actuator>
  </transmission>
  <link name="front_right_coxa_link">
    <visual>
      <origin rpy="0 0 3.14159265359" xyz="-0.002 -0.016 0"/>
      <geometry>
        <mesh filename="package://open_critter/meshes/collada/coxa_rear.dae"/>
      </geometry>
    </visual>
    <collision>
      <origin rpy="0 0 3.14159265359" xyz="-0.002 -0.016 0"/>
      <geometry>
        <mesh filename="package://open_critter/meshes/collada/coxa_rear.dae"/>
      </geometry>
    </collision>
    <inertial>
      <origin rpy="0 0 0" xyz="0 0 0"/>
      <geometry>
        <box size="0.04 0.01 0.03"/>
      </geometry>
      <mass value="0.001"/>
      <inertia ixx="8.33333333333e-08" ixy="0" ixz="0" iyy="2.08333333333e-07" iyz="0" izz="2.08333333333e-07"/>
    </inertial>
  </link>
  <gazebo reference="front_right_coxa_link">
    <gravity>true</gravity>
    <selfCollide>true</selfCollide>
  </gazebo>
  <joint name="front_right_femur_servo_to_coxa_joint" type="fixed">
    <parent link="front_right_coxa_link"/>
    <child link="front_right_femur_servo"/>
    <origin rpy="0 0 0" xyz="0.005 -0.0275 0"/>
  </joint>
  <link name="front_right_femur_servo">
    <visual>
      <origin rpy="0 1.57079632679 0" xyz="0 0 0"/>
      <geometry>
        <mesh filename="package://open_critter/meshes/collada/servo.dae"/>
      </geometry>
    </visual>
    <!-- <collision>
      <origin rpy="0 ${pi/2} ${nyaw}" xyz="0 0 0"/>
      <geometry>
        <mesh filename="package://open_critter/meshes/collada/servo.dae"/>
      </geometry>
    </collision> -->
    <inertial>
      <origin rpy="0 1.57079632679 0" xyz="0 0 0"/>
      <geometry>
        <box size="0.02 0.01 0.03"/>
      </geometry>
      <mass value="0.009"/>
      <inertia ixx="7.5e-07" ixy="0" ixz="0" iyy="9.75e-07" iyz="0" izz="9.75e-07"/>
    </inertial>
  </link>
  <joint name="front_right_femur_joint" type="revolute">
    <parent link="front_right_femur_servo"/>
    <child link="front_right_femur_link"/>
    <origin rpy="-0.392699081699 0 0" xyz="-0.005 0 0.005"/>
    <limit effort="10" lower="-1.0" upper="1.0" velocity="4.0"/>
    <axis xyz="1.0 0 0"/>
  </joint>
  <transmission name="front_right_femur_transmission">
    <type>transmission_interface/SimpleTransmission</type>
    <joint name="front_right_femur_joint">
      <hardwareInterface>hardware_interface/PositionJointInterface</hardwareInterface>
    </joint>
    <actuator name="front_right_femur_actuator">
      <hardwareInterface>hardware_interface/PositionJointInterface</hardwareInterface>
      <mechanicalReduction>1.0</mechanicalReduction>
      <motorTorqueConstant>10</motorTorqueConstant>
    </actuator>
  </transmission>
  <link name="front_right_femur_link">
    <visual>
      <origin rpy="0 0 0" xyz="0.0025 -0.0275 0"/>
      <geometry>
        <mesh filename="package://open_critter/meshes/collada/femur.dae"/>
      </geometry>
    </visual>
    <collision>
      <origin rpy="0 0 0" xyz="0.0025 -0.0275 0"/>
      <geometry>
        <mesh filename="package://open_critter/meshes/collada/femur.dae"/>
      </geometry>
    </collision>
    <inertial>
      <origin rpy="0 0 0" xyz="0 0 0"/>
      <geometry>
        <box size="0.05 0.01 0.03"/>
      </geometry>
      <mass value="0.002"/>
      <inertia ixx="1.66666666667e-07" ixy="0" ixz="0" iyy="5.66666666667e-07" iyz="0" izz="5.66666666667e-07"/>
    </inertial>
  </link>
  <gazebo reference="front_right_femur_link">
    <gravity>true</gravity>
    <selfCollide>true</selfCollide>
  </gazebo>
  <joint name="front_right_tibia_joint" type="revolute">
    <parent link="front_right_femur_link"/>
    <child link="front_right_tibia_servo"/>
    <origin rpy="-0.392699081699 0 0" xyz="0 -0.055 0"/>
    <limit effort="10" lower="-1.0" upper="1.0" velocity="4.0"/>
    <axis xyz="-1.0 0 0"/>
    <dynamics friction="0.7"/>
  </joint>
  <transmission name="front_right_tibia_transmission">
    <type>transmission_interface/SimpleTransmission</type>
    <joint name="front_right_tibia_joint">
      <hardwareInterface>hardware_interface/PositionJointInterface</hardwareInterface>
    </joint>
    <actuator name="front_right_tibia_actuator">
      <hardwareInterface>hardware_interface/PositionJointInterface</hardwareInterface>
      <mechanicalReduction>1.0</mechanicalReduction>
      <motorTorqueConstant>10</motorTorqueConstant>
    </actuator>
  </transmission>
  <link name="front_right_tibia_servo">
    <visual>
      <origin rpy="0 1.57079632679 0" xyz="0.005 0 -0.005"/>
      <geometry>
        <mesh filename="package://open_critter/meshes/collada/servo.dae"/>
      </geometry>
    </visual>
    <!-- <collision>
      <origin rpy="0 ${pi/2} ${nyaw}" xyz="${side*servo_x} 0 -0.005"/>
      <geometry>
        <mesh filename="package://open_critter/meshes/collada/servo.dae"/>
      </geometry>
    </collision> -->
    <inertial>
      <origin rpy="0 1.57079632679 0" xyz="0.005 0 -0.005"/>
      <geometry>
        <box size="0.02 0.01 0.03"/>
      </geometry>
      <mass value="0.009"/>
      <inertia ixx="7.5e-07" ixy="0" ixz="0" iyy="9.75e-07" iyz="0" izz="9.75e-07"/>
    </inertial>
  </link>
  <joint name="front_right_tibia_servo_to_femur_joint" type="fixed">
    <parent link="front_right_tibia_servo"/>
    <child link="front_right_tibia_link"/>
    <origin rpy="0 0 0" xyz="0 0 0"/>
  </joint>
  <link name="front_right_tibia_link">
    <visual>
      <origin rpy="0 0 0" xyz="-0.0025 0 -0.03"/>
      <geometry>
        <mesh filename="package://open_critter/meshes/collada/tibia_front.dae"/>
      </geometry>
    </visual>
    <collision>
      <origin rpy="0 0 0" xyz="-0.0025 0 -0.03"/>
      <geometry>
        <mesh filename="package://open_critter/meshes/collada/tibia_front.dae"/>
      </geometry>
    </collision>
    <inertial>
      <origin rpy="0 0 0" xyz="0 0 0"/>
      <geometry>
        <box size="0.1 0.005 0.005"/>
      </geometry>
      <mass value="0.001"/>
      <inertia ixx="4.16666666667e-09" ixy="0" ixz="0" iyy="8.35416666667e-07" iyz="0" izz="8.35416666667e-07"/>
    </inertial>
  </link>
  <gazebo reference="front_right_tibia_link">
    <mu1 value="5.0"/>
    <mu2 value="0.5"/>
    <kp value="10000000.0"/>
    <kd value="1.0"/>
    <fdir1 value="1 0 0"/>
    <turnGravityOff>false</turnGravityOff>
    <selfCollide>true</selfCollide>
  </gazebo>
  <joint name="front_right_tibia_paw_joint" type="fixed">
    <parent link="front_right_tibia_link"/>
    <child link="front_right_paw_link"/>
    <origin rpy="0 0 0" xyz="0.0035 0 -0.08"/>
  </joint>
  <link name="front_right_paw_link">
    <visual>
      <origin rpy="0 0 0" xyz="0 0 0"/>
      <geometry>
        <sphere radius="0.005"/>
      </geometry>
    </visual>
    <collision>
      <origin rpy="0 0 0" xyz="0 0 0"/>
      <geometry>
        <sphere radius="0.005"/>
      </geometry>
    </collision>
    <inertial>
      <origin rpy="0 0 0" xyz="0 0 0"/>
      <geometry>
        <sphere radius="0.005"/>
      </geometry>
      <mass value="0.001"/>
      <inertia ixx="1e-08" ixy="0" ixz="0" iyy="1e-08" iyz="0" izz="1e-08"/>
    </inertial>
  </link>
  <gazebo reference="front_right_paw_link">
    <gravity>true</gravity>
    <selfCollide>true</selfCollide>
    <mu1>0.1</mu1>
    <mu2>0.1</mu2>
    <kp>1000000.0</kp>
    <kd>1.0</kd>
    <fdir1>0 1 0</fdir1>
    <maxContacts>1</maxContacts>
    <minDepth>0.0001</minDepth>
    <collision name="front_right__paw_link_collision">
      <geometry>
        <sphere>
          <radius>0.005</radius>
        </sphere>
      </geometry>
      <surface>
        <friction>
          <torsional>
            <coefficient>10</coefficient>
            <use_patch_radius>false</use_patch_radius>
            <surface_radius>0.01</surface_radius>
            <patch_radius>0.01</patch_radius>
          </torsional>
        </friction>
        <contact>
          <poissons_ratio>0.01</poissons_ratio>
          <elastic_modulus>1e8</elastic_modulus>
        </contact>
      </surface>
    </collision>
    <material>Gazebo/Red</material>
  </gazebo>
  <gazebo>
    <plugin filename="libgazebo_ros_control.so" name="gazebo_ros_control">
      <robotNamespace>/open_critter</robotNamespace>
    </plugin>
  </gazebo>
  <gazebo>
    <plugin filename="libgazebo_ros_p3d.so" name="p3d_base_controller">
      <alwaysOn>true</alwaysOn>
      <updateRate>100.0</updateRate>
      <bodyName>base_link</bodyName>
      <topicName>/gazebo/odom</topicName>
      <gaussianNoise>0.00001</gaussianNoise>
      <frameName>world</frameName>
      <xyzOffsets>0 0 0</xyzOffsets>
      <rpyOffsets>0 0 0</rpyOffsets>
    </plugin>
  </gazebo>
</robot>
